Workbook

Sheet العاملين الأمانة العامة
A1: # | B1: كود | C1: الرقم الذاتي | D1: الاسم الأول | E1: اسم الأب | F1: الكنية | G1: الاسم الثلاثي | H1: اسم الأم والكنية | I1: الرقم الوطني | J1: الجنسية | K1: المحافظة | L1: المنطقة - المدينة | M1: الناحية | N1: محل الولادة | O1: تاريخ الولادة | P1: القيد | Q1: الجنس | R1: رقم الهاتف | S1: الوضع العائلي | T1: عدد الزوجات | U1: عدد الأبناء | V1: السوية التنظيمية الأولى | W1: السوية التنظيمية الثانية | X1: السوية التنظيمية الثالثة | Y1: السوية التنظيمية الرابعة | Z1: السوية التنظيمية الخامسة | AA1: السوية التنظيمية السادسة | AB1: المسمى الوظيفي الحالي | AC1: مثبت-متعاقد | AD1: الحالة | AE1: تاريخ التعيين | AF1: نمط التعيين أو التعاقد | AG1: اذكر نمط التعيين أو التعاقد | AH1: الفئة الوظيفية الحالية | AI1: المؤهل العلمي المعيين على أساسه أو المعدل فئته عليه | AJ1: الاختصاص | AK1: السكن (المحافظة) | AL1: السكن (المنطقة - المدينة) | AM1: نوع السكن | AN1: هل ( الزوج /الزوجة ) موظف في القطاع الحكومي؟ | AO1: الاسم الثلاثي لــ( الزوج/الزوجة ) في حال كان موظف | AP1: الجهة التي يعمل بها (الزوج/الزوجة) في حال كان موظف | AQ1: الحالة الصحية | AR1: تفصيل الإصابة أو المرض | AS1: زمرة الدم | AT1: نوع الشهادة الحاصل عليها | AU1: وجود الوثيقة | AV1: الجامعة | AW1: الكلية-المعهد | AX1: الاختصاص2 | AY1: عام الحصول عليها | AZ1: هل لديك شهادة عليا في الإدارة؟ | BA1: ملاحظات | BB1: مكان الدوام | BC1: ملاك أو خارج الملاك | BD1: _id | BE1: _index | BF1: آخر راتب مقطوع
A2: 1 | B2: 122 | C2: 1634548 | D2: ابراهيم | E2: فؤاد | F2: حسن | G2: =CONCATENATE(TRIM(الجدول2[[#This Row],[الاسم الأول]])," ",TRIM(الجدول2[[#This Row],[اسم الأب]])," ",TRIM(الجدول2[[#This Row],[الكنية]])) -> ابراهيم فؤاد حسن | H2: نبيلة سليمان | I2: 10090039368 | J2: سوري | K2: طرطوس | L2: طرطوس | M2: مركز منطقة طرطوس | N2: دمشق | O2: 35141 | P2: حرف بنمرة ٣ | Q2: ذكر | R2: 0935284766 | S2: عازب | V2: وزارة الإدارة المحلية و البيئة | W2: الأمانة العامة للمحافظة | X2: الأمانة العامة لمحافظة طرطوس | Y2: مديرية المعلوماتية | Z2: دائرة النظم والبرمجيات | AA2: شبعة النظم والتحليل | AB2: مهندس | AC2: مثبت | AD2: على رأس عمله | AE2: 45522 | AF2: فرز مهندسين | AH2: الفئة الاولى | AI2: إجازة جامعية 5 سنوات | AJ2: معلوماتية | AK2: طرطوس | AL2: بانياس | AM2: إيجار | AN2: لا | AQ2: سليم | AS2: A+ | AT2: إجازة جامعية 5 سنوات | AU2: نعم | AV2: تشرين | AW2: معلوماتية | AX2: برمجيات ونظم المعلومات | AY2: 44180 | AZ2: لا | BB2: ضمن المبنى | BC2: داخل الملاك | BD2: 524131068 | BE2: 6320 | BF2: 943000
A3: 2 | B3: 306 | C3: 1634542 | D3: احمد | E3: صلاح | F3: ابراهيم | G3: =CONCATENATE(TRIM(الجدول2[[#This Row],[الاسم الأول]])," ",TRIM(الجدول2[[#This Row],[اسم الأب]])," ",TRIM(الجدول2[[#This Row],[الكنية]])) -> احمد صلاح ابراهيم | H3: عواطف ديب | I3: 10010075916 | J3: سوري | K3: طرطوس | L3: الدريكيش | M3: حمين | N3: طرطوس | O3: 35796 | P3: خراب ٧٠٤ | Q3: ذكر | R3: 0934756259 | S3: عازب | V3: وزارة الإدارة المحلية و البيئة | W3: الأمانة العامة للمحافظة | X3: الأمانة العامة لمحافظة طرطوس | Y3: مديرية التنمية الإدارية | Z3: دائرة التنظيم المؤسساتي | AA3: شعبة تطوير نظم المعلومات | AB3: مطور نظم | AC3: مثبت | AD3: على رأس عمله | AE3: 45522 | AF3: فرز مهندسين | AH3: الفئة الاولى | AI3: إجازة جامعية 5 سنوات | AJ3: هندسة تكنولوجيا المعلومات | AK3: طرطوس | AL3: طرطوس | AM3: ملك | AN3: لا | AQ3: سليم | AS3: A+ | AT3: إجازة جامعية 5 سنوات | AU3: نعم | AV3: طرطوس | AW3: هندسة تكنولوجيا المعلومات | AX3: تكنولوجيا المعلومات | AY3: 44138 | AZ3: لا | BB3: ضمن المبنى | BC3: داخل الملاك | BD3: 522373325 | BE3: 944 | BF3: 943000
A4: 3 | B4: 416 | C4: 1634542 | D4: احمد | E4: كامل | F4: حمدان | G4: =CONCATENATE(TRIM(الجدول2[[#This Row],[الاسم الأول]])," ",TRIM(الجدول2[[#This Row],[اسم الأب]])," ",TRIM(الجدول2[[#This Row],[الكنية]])) -> احمد كامل حمدان | H4: سهام طريفي | I4: 10260020568 | J4: سوري | K4: طرطوس | L4: الشيخ بدر | M4: مركز منطقة الشيخ بدر | N4: طرطوس | O4: 34133 | P4: سريجيس ٣٥ | Q4: ذكر | R4: 0994302012 | S4: متزوج | T4: 1 | U4: 0 | V4: وزارة الإدارة المحلية و البيئة | W4: الأمانة العامة للمحافظة | X4: الأمانة العامة لمحافظة طرطوس | Y4: مديرية التنمية الإدارية | Z4: دائرة التنظيم المؤسساتي | AA4: شعبة تبسيط الإجراءات | AB4: مبسط احراءات | AC4: مثبت | AD4: على رأس عمله | AE4: 45522 | AF4: فرز مهندسين | AH4: الفئة الاولى | AI4: إجازة جامعية 5 سنوات | AJ4: هنسة كهربائية | AK4: طرطوس | AL4: الشيخ بدر | AM4: ملك | AN4: لا | AQ4: سليم | AS4: A+ | AT4: إجازة جامعية 5 سنوات | AU4: نعم | AV4: تشرين | AW4: هندسة كهربائية | AX4: طاقة | AY4: 44392 | AZ4: لا | BB4: ضمن المبنى | BC4: داخل الملاك | BD4: 522369389 | BE4: 922 | BF4: 943000
A5: 4 | B5: 493 | D5: احمد | E5: محمد | F5: يوسف | G5: =CONCATENATE(TRIM(الجدول2[[#This Row],[الاسم الأول]])," ",TRIM(الجدول2[[#This Row],[اسم الأب]])," ",TRIM(الجدول2[[#This Row],[الكنية]])) -> احمد محمد يوسف | H5: جمالي محمد | I5: 10010114596 | J5: سوري | K5: طرطوس | L5: طرطوس | M5: مركز منطقة طرطوس | N5: طرطوس | O5: 29438 | P5: سجنو١١ | Q5: ذكر | R5: 0999856210 | S5: متزوج | T5: 1 | U5: 3 | V5: وزارة الإدارة المحلية و البيئة | W5: الأمانة العامة للمحافظة | X5: الأمانة العامة لمحافظة طرطوس | Y5: مكتب التنمية المحلية | AB5: إداري | AC5: مثبت | AD5: على رأس عمله | AE5: 41294 | AF5: مسابقة | AH5: الفئة الثانية | AI5: شهاد ثانوية | AK5: طرطوس | AL5: طرطوس | AM5: ملك | AN5: نعم | AO5: عزه معين معلا | AP5: مديرية الصحة | AQ5: سليم | AS5: A+ | AT5: شهادة ثانوية | AU5: نعم | AX5: ادبي | AY5: 37480 | AZ5: لا | BB5: ضمن المبنى | BC5: داخل الملاك | BD5: 526022531 | BE5: 9258 | BF5: 1243000
A6: 5 | B6: 533 | C6: 16066203 | D6: احمد | E6: ميهوب | F6: علي | G6: =CONCATENATE(TRIM(الجدول2[[#This Row],[الاسم الأول]])," ",TRIM(الجدول2[[#This Row],[اسم الأب]])," ",TRIM(الجدول2[[#This Row],[الكنية]])) -> احمد ميهوب علي | H6: اميرة عمار | I6: 10100035265 | J6: سوري | K6: طرطوس | L6: طرطوس | M6: مركز منطقة طرطوس | N6: باب النور | O6: 28235 | P6: باب النور ١٧ | Q6: ذكر | R6: 0982325362 | S6: عازب | V6: وزارة الإدارة المحلية و البيئة | W6: الأمانة العامة للمحافظة | X6: الأمانة العامة لمحافظة طرطوس | Y6: تكليف | AB6: عامل حدائق | AC6: مثبت | AD6: على رأس عمله | AE6: 37469 | AF6: تعاقد مباشر | AH6: الفئة الخامسة | AI6: شهاد ثانوية | AK6: طرطوس | AL6: القدموس | AM6: ملك | AN6: لا | AQ6: سليم | AS6: B+ | AT6: شهادة إعدادية | AU6: نعم | AY6: 37461 | AZ6: لا | BA6: مكلف لدى بلدية الدي | BB6: خارج المبنى | BC6: داخل الملاك | BD6: 524131953 | BE6: 6335 | BF6: 1098000
A7: 6 | B7: 559 | C7: 1639597 | D7: احمد | E7: يونس | F7: ريا | G7: =CONCATENATE(TRIM(الجدول2[[#This Row],[الاسم الأول]])," ",TRIM(الجدول2[[#This Row],[اسم الأب]])," ",TRIM(الجدول2[[#This Row],[الكنية]])) -> احمد يونس ريا | H7: مسيكة ريا | I7: 10010108388 | J7: سوري | K7: طرطوس | L7: بانياس | M7: تالين | N7: تعنيتا | O7: 28856 | P7: تعنيتا | Q7: ذكر | R7: 0988570690 | S7: متزوج | T7: 1 | U7: 3 | V7: وزارة الإدارة المحلية و البيئة | W7: الأمانة العامة للمحافظة | X7: الأمانة العامة لمحافظة طرطوس | Y7: مديرية إدارة النفايات الصلبة | Z7: القسم الفني | AB7: عامل فرز | AC7: متعاقد | AD7: على رأس عمله | AE7: 44927 | AF7: مسابقة مركزية | AH7: الفئة الرابعة | AI7: شهادة إعدادية | AK7: طرطوس | AL7: طرطوس | AM7: أقارب | AN7: لا | AQ7: سليم | AS7: A+ | AT7: شهادة إعدادية | AU7: لا | AY7: 33077 | AZ7: لا | BB7: خارج المبنى | BC7: داخل الملاك | BD7: 523228997 | BE7: 3327 | BF7: 918870
A8: 7 | B8: 577 | C8: 1121424 | D8: اديب | E8: صالح | F8: ملحم | G8: =CONCATENATE(TRIM(الجدول2[[#This Row],[الاسم الأول]])," ",TRIM(الجدول2[[#This Row],[اسم الأب]])," ",TRIM(الجدول2[[#This Row],[الكنية]])) -> اديب صالح ملحم | H8: جميلة محفوض | I8: 10160156944 | J8: سوري | K8: طرطوس | L8: صافيتا | M8: مركز منطقة صافيتا | N8: رويسة حمدان | O8: 35404 | P8: رويسة حمدان٣٨ | Q8: ذكر | R8: 0934825299 | S8: متزوج | T8: 1 | U8: 3 | V8: وزارة الإدارة المحلية و البيئة | W8: الأمانة العامة للمحافظة | X8: الأمانة العامة لمحافظة طرطوس | Y8: مديرية المجالس المحلية | Z8: دائرة المكتب التنفيذي | AA8: لدى عضو مكتب تنفيذي | AB8: مستخدم | AC8: مثبت | AD8: على رأس عمله | AE8: 35745 | AF8: تعاقد مباشر | AH8: الفئة الخامسة | AI8: شهادة إعدادية | AK8: طرطوس | AL8: طرطوس | AM8: ملك | AN8: لا | AQ8: سليم | AS8: O+ | AT8: شهادة إعدادية | AU8: نعم | AY8: 31250 | AZ8: لا | BB8: ضمن المبنى | BC8: داخل الملاك | BD8: 522408927 | BE8: 1118 | BF8: 1098000
A9: 8 | B9: 758 | C9: 1634809 | D9: الهام | E9: علي | F9: اسماعيل | G9: =CONCATENATE(TRIM(الجدول2[[#This Row],[الاسم الأول]])," ",TRIM(الجدول2[[#This Row],[اسم الأب]])," ",TRIM(الجدول2[[#This Row],[الكنية]])) -> الهام علي اسماعيل | H9: منى اسماعيل | I9: 10010097009 | J9: سوري | K9: طرطوس | L9: طرطوس | M9: مركز منطقة طرطوس | N9: طرطوس | O9: 33318 | P9: حبرون ١٢ | Q9: انثى | R9: 0994231145 | S9: متزوج | U9: 2 | V9: وزارة الإدارة المحلية و البيئة | W9: الأمانة العامة للمحافظة | X9: الأمانة العامة لمحافظة طرطوس | Y9: تكليف | AB9: مراقب فني | AC9: متعاقد | AD9: على رأس عمله | AE9: 41294 | AF9: مسابقة | AH9: الفئة الثانية | AI9: معهد متوسط | AJ9: مراقب فني - مساحة | AK9: طرطوس | AL9: صافيتا | AM9: ملك | AN9: لا | AQ9: سليم | AS9: B+ | AT9: معهد متوسط | AU9: نعم | AV9: اللاذقية | AW9: معهد مراقبين فنيين | AX9: مساحة | AY9: 40544 | AZ9: لا | BA9: مكافة لدى بلدة الطليعي | BB9: خارج المبنى | BC9: داخل الملاك | BD9: 526603924 | BE9: 13980 | BF9: 1243000
A10: 9 | B10: 870 | C10: 1628604 | D10: اناغيم | E10: محمد علي | F10: أبو خضور | G10: =CONCATENATE(TRIM(الجدول2[[#This Row],[الاسم الأول]])," ",TRIM(الجدول2[[#This Row],[اسم الأب]])," ",TRIM(الجدول2[[#This Row],[الكنية]])) -> اناغيم محمد علي أبو خضور | H10: رغداء ابو خضور | I10: 12010053981 | J10: سوري | K10: طرطوس | L10: طرطوس | M10: مركز منطقة طرطوس | N10: مشفى درعا | O10: 35474 | P10: دعا٨١٧ | Q10: انثى | R10: 0935077605 | S10: عازب | V10: وزارة الإدارة المحلية و البيئة | W10: الأمانة العامة للمحافظة | X10: الأمانة العامة لمحافظة طرطوس | Y10: مديرية إدارة النفايات الصلبة | Z10: القسم الإداري | AB10: مهندسة | AC10: مثبت | AD10: على رأس عمله | AE10: 45522 | AF10: فرز مهندسين | AH10: الفئة الاولى | AI10: إجازة جامعية 5 سنوات | AJ10: هندسة تكنولوجيا المعلومات والاتصالات | AK10: طرطوس | AL10: طرطوس | AM10: ملك | AN10: لا | AQ10: سليم | AS10: O+ | AT10: إجازة جامعية 5 سنوات | AU10: نعم | AV10: جامعة طرطوس | AW10: كلية الهندسة المعلوماتية | AX10: تكنولوجيا المعلومات | AY10: 44138 | AZ10: لا | BB10: ضمن المبنى | BC10: داخل الملاك | BD10: 523173918 | BE10: 2897 | BF10: 943000
A11: 10 | B11: 878 | D11: انتصار | E11: اخرس | F11: نجلا | G11: =CONCATENATE(TRIM(الجدول2[[#This Row],[الاسم الأول]])," ",TRIM(الجدول2[[#This Row],[اسم الأب]])," ",TRIM(الجدول2[[#This Row],[الكنية]])) -> انتصار اخرس نجلا | H11: سميعة البري | I11: 10030013865 | J11: سوري | K11: طرطوس | L11: طرطوس | M11: السودا | N11: مرقية | O11: 27719 | P11: عزيت ٢١ | Q11: انثى | R11: 0994097884 | S11: متزوج | U11: 2 | V11: وزارة الإدارة المحلية و البيئة | W11: الأمانة العامة للمحافظة | X11: الأمانة العامة لمحافظة طرطوس | Y11: مديرية الشؤون المالية | Z11: دائرة الوحدات الإدارية | AB11: مراسلة | AC11: مثبت | AD11: على رأس عمله | AE11: 43905 | AF11: مسابقة | AH11: الفئة الخامسة | AI11: شهادة إعدادية | AK11: طرطوس | AL11: طرطوس | AM11: ملك | AN11: نعم | AO11: طلال حبيب تفاحة | AP11: مجلس مدينة طرطوس | AQ11: سليم | AS11: A+ | AT11: شهادة إعدادية | AU11: نعم | AY11: 33078 | AZ11: لا | BB11: ضمن المبنى | BC11: داخل الملاك | BD11: 523952423 | BE11: 4800 | BF11: 994128
A12: 11 | B12: 875 | D12: انتصار | E12: عوض | F12: الظروف | G12: =CONCATENATE(TRIM(الجدول2[[#This Row],[الاسم الأول]])," ",TRIM(الجدول2[[#This Row],[اسم الأب]])," ",TRIM(الجدول2[[#This Row],[الكنية]])) -> انتصار عوض الظروف | H12: معينه محمود | I12: 10130000188 | J12: سوري | K12: طرطوس | L12: طرطوس | M12: مركز منطقة طرطوس | N12: طرطوس | O12: 30051 | P12: خراب ١٨٢٨ | Q12: انثى | R12: 0931832037 | S12: متزوج | U12: 3 | V12: وزارة الإدارة المحلية و البيئة | W12: الأمانة العامة للمحافظة | X12: الأمانة العامة لمحافظة طرطوس | Y12: مديرية التنمية الإدارية | Z12: دائرة الديوان العام | AA12: شعبة الارشفة | AB12: عامل طباعة | AC12: متعاقد | AD12: على رأس عمله | AE12: 43905 | AF12: مسابقة | AH12: الفئة الرابعة | AI12: شهادة إعدادية | AK12: طرطوس | AL12: طرطوس | AM12: ملك | AN12: لا | AQ12: سليم | AS12: O+ | AT12: معهد متوسط | AU12: نعم | AV12: طرطوس | AW12: معهد فنون | AX12: فنون | AY12: 35256 | AZ12: لا | BB12: ضمن المبنى | BC12: داخل الملاك | BD12: 524057958 | BE12: 5736 | BF12: 1001181
A13: 12 | B13: 883 | C13: 1634554 | D13: انس | E13: حكمت | F13: محمود | G13: =CONCATENATE(TRIM(الجدول2[[#This Row],[الاسم الأول]])," ",TRIM(الجدول2[[#This Row],[اسم الأب]])," ",TRIM(الجدول2[[#This Row],[الكنية]])) -> انس حكمت محمود | H13: دعد سليمان | I13: 10260033092 | J13: سوري | K13: طرطوس | L13: طرطوس | M13: مركز منطقة طرطوس | N13: طرطوس | O13: 34713 | P13: تنغري ١٦ | Q13: ذكر | R13: 0998406399 | S13: عازب | V13: وزارة الإدارة المحلية و البيئة | W13: الأمانة العامة للمحافظة | X13: الأمانة العامة لمحافظة طرطوس | Y13: مديرية دعم القرار والتخطيط الإقليمي | Z13: دائرة الدعم الفني | AB13: مهندس | AC13: مثبت | AD13: على رأس عمله | AE13: 45494 | AF13: فرز مهندسين | AH13: الفئة الاولى | AI13: إجازة جامعية 5 سنوات | AJ13: هندسة معمارية | AK13: طرطوس | AL13: طرطوس | AM13: ملك | AN13: لا | AQ13: سليم | AS13: A- | AT13: إجازة جامعية 5 سنوات | AU13: نعم | AV13: اللاذقية | AW13: عمارة | AX13: عمارة | AY13: 44117 | AZ13: لا | BB13: ضمن المبنى | BC13: داخل الملاك | BD13: 523968947 | BE13: 4949 | BF13: 943000
A14: 13 | B14: 930 | C14: 1639558 | D14: اياد | E14: علي | F14: حبيب | G14: =CONCATENATE(TRIM(الجدول2[[#This Row],[الاسم الأول]])," ",TRIM(الجدول2[[#This Row],[اسم الأب]])," ",TRIM(الجدول2[[#This Row],[الكنية]])) -> اياد علي حبيب | H14: غالية حسن | I14: 10120001092 | J14: سوري | K14: طرطوس | L14: القدموس | M14: الطواحين | N14: شمسين | O14: 30594 | P14: الطواحين ٢٠ | Q14: ذكر | R14: 0988801589 | S14: متزوج | T14: 1 | U14: 2 | V14: وزارة الإدارة المحلية و البيئة | W14: الأمانة العامة للمحافظة | X14: الأمانة العامة لمحافظة طرطوس | Y14: مديرية الخدمات العامة | Z14: دائرة الآليات | AA14: شعبة المرآب | AB14: سائق | AC14: متعاقد | AD14: على رأس عمله | AE14: 45077 | AF14: مسابقة مركزية | AH14: الفئة الرابعة | AI14: قراءة وكتابة | AK14: طرطوس | AL14: القدموس | AM14: ملك | AN14: لا | AQ14: سليم | AS14: O+ | AT14: قراءة وكتابة | AZ14: لا | BB14: ضمن المبنى | BC14: داخل الملاك | BD14: 526581613 | BE14: 13691 | BF14: 918870
A15: 14 | B15: 957 | C15: 1634546 | D15: اية | E15: امين | F15: دلول | G15: =CONCATENATE(TRIM(الجدول2[[#This Row],[الاسم الأول]])," ",TRIM(الجدول2[[#This Row],[اسم الأب]])," ",TRIM(الجدول2[[#This Row],[الكنية]])) -> اية امين دلول | H15: سميرا ابراهيم | I15: 10010044403 | J15: سوري | K15: طرطوس | L15: طرطوس | M15: مركز منطقة طرطوس | N15: طرطوس | O15: 35707 | P15: الشيخ سعد ٤٩ | Q15: انثى | R15: 0991647079 | S15: عازب | V15: وزارة الإدارة المحلية و البيئة | W15: الأمانة العامة للمحافظة | X15: الأمانة العامة لمحافظة طرطوس | Y15: مديرية المعلوماتية | Z15: دائرة الشبكات والدعم الفني | AA15: شعبة الشبكات | AB15: مهندس | AC15: مثبت | AD15: على رأس عمله | AE15: 45525 | AF15: فرز مهندسين | AH15: الفئة الاولى | AI15: إجازة جامعية 5 سنوات | AJ15: معلوماتية | AK15: طرطوس | AL15: طرطوس | AM15: ملك | AN15: لا | AQ15: سليم | AS15: O+ | AT15: إجازة جامعية 5 سنوات | AU15: نعم | AV15: تشرين | AW15: معلوماتية | AX15: النظم والشبكات الحاسوبية | AY15: 44307 | AZ15: لا | BB15: ضمن المبنى | BC15: داخل الملاك | BD15: 524096662 | BE15: 6070 | BF15: 943000
A16: 15 | B16: 958 | C16: 1634574 | D16: اية | E16: حمد | F16: شما | G16: =CONCATENATE(TRIM(الجدول2[[#This Row],[الاسم الأول]])," ",TRIM(الجدول2[[#This Row],[اسم الأب]])," ",TRIM(الجدول2[[#This Row],[الكنية]])) -> اية حمد شما | H16: وداد زيني | I16: 10090092308 | J16: سوري | K16: طرطوس | L16: بانياس | M16: تالين | N16: تعنيتا | O16: 35980 | P16: تعنيتا ٣٧ | Q16: انثى | R16: 0953609418 | S16: عازب | V16: وزارة الإدارة المحلية و البيئة | W16: الأمانة العامة للمحافظة | X16: الأمانة العامة لمحافظة طرطوس | Y16: مديرية المعلوماتية | Z16: دائرة الشبكات والدعم الفني | AA16: شعبة الشبكات والاتصالات | AB16: مهندس | AC16: مثبت | AD16: على رأس عمله | AE16: 45525 | AF16: فرز مهندسين | AH16: الفئة الاولى | AI16: إجازة جامعية 5 سنوات | AJ16: معلوماتية | AK16: طرطوس | AL16: بانياس | AM16: ملك | AN16: لا | AQ16: سليم | AS16: A- | AT16: إجازة جامعية 5 سنوات | AU16: نعم | AV16: اللادقية | AW16: معلوماتية | AX16: نظم شبكات معلوماتية | AY16: 44835 | AZ16: لا | BB16: ضمن المبنى | BC16: داخل الملاك | BD16: 524086357 | BE16: 5985 | BF16: 943000
A17: 16 | B17: 964 | C17: 1419916 | D17: ايفين | E17: احمد | F17: عبدالله | G17: =CONCATENATE(TRIM(الجدول2[[#This Row],[الاسم الأول]])," ",TRIM(الجدول2[[#This Row],[اسم الأب]])," ",TRIM(الجدول2[[#This Row],[الكنية]])) -> ايفين احمد عبدالله | H17: سحر اسعد | I17: 04120082246 | J17: سوري | K17: طرطوس | L17: صافيتا | M17: مركز منطقة صافيتا | N17: سميكة | O17: 32874 | P17: دلبة ٣٤ | Q17: انثى | R17: 0997599571 | S17: متزوج | U17: 3 | V17: وزارة الإدارة المحلية و البيئة | W17: الأمانة العامة للمحافظة | X17: الأمانة العامة لمحافظة طرطوس | Y17: تكليف | AB17: مهندسة | AC17: مثبت | AD17: على رأس عمله | AE17: 41981 | AF17: فرز مهندسين | AH17: الفئة الاولى | AI17: إجازة جامعية 5 سنوات | AJ17: هندسة مدنية | AK17: طرطوس | AL17: صافيتا | AM17: ملك | AN17: لا | AQ17: سليم | AS17: O+ | AT17: إجازة جامعية 5 سنوات | AU17: نعم | AV17: اللاذقية | AW17: مدني | AX17: ادارة تشييد | AY17: 41431 | AZ17: لا | BA17: مكلف لدى بلدية بشبطة | BB17: خارج المبنى | BC17: داخل الملاك | BD17: 523961740 | BE17: 4884 | BF17: 1292226
A18: 17 | B18: 970 | C18: 1408949 | D18: ايمان | E18: بديع | F18: ابراهيم | G18: =CONCATENATE(TRIM(الجدول2[[#This Row],[الاسم الأول]])," ",TRIM(الجدول2[[#This Row],[اسم الأب]])," ",TRIM(الجدول2[[#This Row],[الكنية]])) -> ايمان بديع ابراهيم | H18: لينا مصطفى | I18: 10160160847 | J18: سوري | K18: طرطوس | L18: صافيتا | M18: مركز منطقة صافيتا | N18: صافيتا الكنايس | O18: 29184 | P18: جورة الشمبور ١٩ | Q18: انثى | R18: 0935202818 | S18: متزوج | U18: 3 | V18: وزارة الإدارة المحلية و البيئة | W18: الأمانة العامة للمحافظة | X18: الأمانة العامة لمحافظة طرطوس | Y18: مديرية المجالس المحلية | Z18: دائرة مجلس المحافظة ومكتبه التنفيذي | AB18: ادارية | AC18: مثبت | AD18: على رأس عمله | AE18: 42137 | AF18: فرز معهد الإدارة العامة INA | AH18: الفئة الاولى | AI18: ماجستير | AJ18: هندسة زراعية شعبة عامة | AK18: طرطوس | AL18: صافيتا | AM18: ملك | AN18: لا | AQ18: سليم | AS18: O+ | AT18: ماجستير | AU18: نعم | AV18: اللاذقية | AW18: هندسة زراعية | AX18: شعبة عامة | AY18: 38191 | AZ18: نعم | BB18: ضمن المبنى | BC18: داخل الملاك | BD18: 523159089 | BE18: 2782 | BF18: 1316292
A19: 18 | B19: 999 | C19: 1564022 | D19: ايمن | E19: ابراهيم | F19: يوسف | G19: =CONCATENATE(TRIM(الجدول2[[#This Row],[الاسم الأول]])," ",TRIM(الجدول2[[#This Row],[اسم الأب]])," ",TRIM(الجدول2[[#This Row],[الكنية]])) -> ايمن ابراهيم يوسف | H19: ليلى سليمان | I19: 10170013932 | J19: سوري | K19: طرطوس | L19: الدريكيش | M19: مركز منطقة الدريكيش | N19: خربة بسماقة | O19: 32626 | P19: خربة بسماقة ٧ | Q19: ذكر | R19: 0994002806 | S19: عازب | V19: وزارة الإدارة المحلية و البيئة | W19: الأمانة العامة للمحافظة | X19: الأمانة العامة لمحافظة طرطوس | Y19: مديرية التنمية الإدارية | Z19: دائرة الديوان العام | AA19: الجاهزية | AB19: عامل طباعة | AC19: متعاقد | AD19: على رأس عمله | AE19: 44054 | AF19: مسابقة | AH19: الفئة الرابعة | AI19: شهادة إعدادية | AK19: طرطوس | AL19: طرطوس | AM19: ملك | AN19: لا | AQ19: سليم | AS19: O+ | AT19: شهادة إعدادية | AU19: نعم | AY19: 38192 | AZ19: لا | BB19: ضمن المبنى | BC19: داخل الملاك | BD19: 524102105 | BE19: 6105 | BF19: 1001241
A20: 19 | B20: 1091 | D20: إماس | E20: علي | F20: فريد | G20: =CONCATENATE(TRIM(الجدول2[[#This Row],[الاسم الأول]])," ",TRIM(الجدول2[[#This Row],[اسم الأب]])," ",TRIM(الجدول2[[#This Row],[الكنية]])) -> إماس علي فريد | H20: يقظه حمود | I20: 10140010401 | J20: سوري | K20: طرطوس | L20: القدموس | M20: حمام واصل | N20: مرويه | O20: 32464 | P20: طرطوس | Q20: انثى | R20: 0992775923 | S20: متزوج | U20: 3 | V20: وزارة الإدارة المحلية و البيئة | W20: الأمانة العامة للمحافظة | X20: الأمانة العامة لمحافظة طرطوس | Y20: تكليف | AB20: مراقب فني | AC20: مثبت | AD20: على رأس عمله | AE20: 40862 | AF20: مسابقة | AH20: الفئة الثانية | AI20: معهد متوسط | AJ20: مراقبين فنيين | AK20: طرطوس | AL20: القدموس | AM20: ملك | AN20: لا | AQ20: سليم | AS20: A+ | AT20: معهد متوسط | AU20: نعم | AV20: جامعة طرطوس | AW20: معهد مراقبين فنيين | AX20: رسم هندسي | AY20: 39741 | AZ20: لا | BA20: مكلفة لدى بلدية حمام واصل | BB20: خارج المبنى | BC20: داخل الملاك | BD20: 528008932 | BE20: 21509 | BF20: 1243000
A21: 20 | B21: 1330 | D21: أميرة | E21: علي | F21: ابراهيم | G21: =CONCATENATE(TRIM(الجدول2[[#This Row],[الاسم الأول]])," ",TRIM(الجدول2[[#This Row],[اسم الأب]])," ",TRIM(الجدول2[[#This Row],[الكنية]])) -> أميرة علي ابراهيم | H21: بهيه خضر | I21: 10220042304 | J21: سوري | K21: طرطوس | L21: الدريكيش | M21: مركز منطقة الدريكيش | N21: طرطوس | O21: 27885 | P21: بقعو27 | Q21: انثى | R21: 0988402925 | S21: عازب | V21: وزارة الإدارة المحلية و البيئة | W21: الأمانة العامة للمحافظة | X21: الأمانة العامة لمحافظة طرطوس | Y21: مديرية المجالس المحلية | Z21: دائرة شؤون الوحدات الادارية | AB21: رئيسة دائرة شؤون الوحدات الادارية | AC21: مثبت | AD21: على رأس عمله | AE21: 41367 | AF21: فرز معهد الإدارة العامة INA | AH21: الفئة الاولى | AI21: ماجستير | AJ21: هندسة زراعية شعبة عامة | AK21: طرطوس | AL21: الدريكيش | AM21: أقارب | AN21: لا | AQ21: سليم | AS21: O+ | AT21: ماجستير | AU21: نعم | AV21: جامعة اللادقية | AW21: هندسة زراعية | AX21: شعبة عامة | AY21: 41113 | AZ21: نعم | BB21: ضمن المبنى | BC21: داخل الملاك | BD21: 523131640 | BE21: 2513 | BF21: 1368162
A22: 21 | B22: 1363 | D22: أية | E22: حبيب | F22: عباس | G22: =CONCATENATE(TRIM(الجدول2[[#This Row],[الاسم الأول]])," ",TRIM(الجدول2[[#This Row],[اسم الأب]])," ",TRIM(الجدول2[[#This Row],[الكنية]])) -> أية حبيب عباس | H22: أمل العجي | I22: 10010000651 | J22: سوري | K22: طرطوس | L22: طرطوس | M22: مركز منطقة طرطوس | N22: طرطوس | O22: 32122 | P22: القمصية33 | Q22: انثى | R22: 0940966854 | S22: متزوج | U22: 2 | V22: وزارة الإدارة المحلية و البيئة | W22: الأمانة العامة للمحافظة | X22: الأمانة العامة لمحافظة طرطوس | Y22: تكليف | AB22: ادارية | AC22: مثبت | AD22: على رأس عمله | AE22: 41295 | AF22: مسابقة | AH22: الفئة الاولى | AI22: إجازة جامعية 4 سنوات | AJ22: تجارة واقتصاد | AK22: طرطوس | AL22: طرطوس | AM22: ملك | AN22: نعم | AO22: مازن عارف محمد | AP22: الخدمات الفنية | AQ22: سليم | AS22: A+ | AT22: إجازة جامعية 4 سنوات | AU22: نعم | AV22: جامعة طرطوس | AW22: كلية الاقتصاد | AX22: تجارة واقتصاد | AY22: 40070 | AZ22: لا | BA22: مكلفة لدى مديرية الخدمات الفنية | BB22: خارج المبنى | BC22: داخل الملاك | BD22: 528085568 | BE22: 22175 | BF22: 1322775
A23: 22 | B23: 1493 | C23: 839044 | D23: باسم | E23: سلمان | F23: احمد | G23: =CONCATENATE(TRIM(الجدول2[[#This Row],[الاسم الأول]])," ",TRIM(الجدول2[[#This Row],[اسم الأب]])," ",TRIM(الجدول2[[#This Row],[الكنية]])) -> باسم سلمان احمد | H23: نوف احمد | I23: 10010161653 | J23: سوري | K23: طرطوس | L23: طرطوس | M23: مركز منطقة طرطوس | N23: بيت كمونة | O23: 27267 | P23: بيت كمونة٥ | Q23: ذكر | R23: 0933367120 | S23: متزوج | T23: 1 | U23: 2 | V23: وزارة الإدارة المحلية و البيئة | W23: الأمانة العامة للمحافظة | X23: الأمانة العامة لمحافظة طرطوس | Y23: مكتب التنمية المحلية | AB23: مهندس | AC23: مثبت | AD23: إجازة بلا أجر | AE23: 36299 | AF23: فرز مهندسين | AH23: الفئة الاولى | AI23: إجازة جامعية 5 سنوات | AJ23: هندسة عمارة | AK23: طرطوس | AL23: طرطوس | AM23: ملك | AN23: نعم | AO23: رباب غانم دبس | AP23: مديرية التربية | AQ23: سليم | AS23: O+ | AT23: إجازة جامعية 5 سنوات | AU23: نعم | AV23: اللاذقية | AW23: هندسة عماره | AX23: عماره | AY23: 36109 | AZ23: لا | BC23: داخل الملاك | BD23: 526021430 | BE23: 9218 | BF23: 1409000
A24: 23 | B24: 1515 | C24: 1639567 | D24: باسم | E24: محمود | F24: حسن | G24: =CONCATENATE(TRIM(الجدول2[[#This Row],[الاسم الأول]])," ",TRIM(الجدول2[[#This Row],[اسم الأب]])," ",TRIM(الجدول2[[#This Row],[الكنية]])) -> باسم محمود حسن | H24: أنيسة داوود | I24: 10010155312 | J24: سوري | K24: طرطوس | L24: طرطوس | M24: مركز منطقة طرطوس | N24: طرطوس | O24: 27931 | P24: ضهر رجب٢٢ | Q24: ذكر | R24: 0991570156 | S24: متزوج | T24: 1 | U24: 3 | V24: وزارة الإدارة المحلية و البيئة | W24: الأمانة العامة للمحافظة | X24: الأمانة العامة لمحافظة طرطوس | Y24: مديرية إدارة النفايات الصلبة | Z24: المركز المتكامل في وادي الهدة | AB24: عامل فرز | AC24: مثبت | AD24: على رأس عمله | AE24: 45083 | AF24: مسابقة | AH24: الفئة الخامسة | AI24: قراءة وكتابة | AK24: طرطوس | AL24: طرطوس | AM24: إيجار | AN24: لا | AQ24: سليم | AS24: B+ | AT24: قراءة وكتابة | AZ24: لا | BB24: خارج المبنى | BC24: داخل الملاك | BD24: 523179790 | BE24: 2958 | BF24: 1098000
A25: 24 | B25: 44099 | C25: 1392338 | D25: براءه | E25: علي | F25: حاج معلا | G25: =CONCATENATE(TRIM(الجدول2[[#This Row],[الاسم الأول]])," ",TRIM(الجدول2[[#This Row],[اسم الأب]])," ",TRIM(الجدول2[[#This Row],[الكنية]])) -> براءه علي حاج معلا | H25: هيام شناتا | I25: 10010079957 | J25: سوري | K25: طرطوس | L25: طرطوس | M25: مركز منطقة طرطوس | N25: طرطوس | O25: 33239 | P25: خراب اسلام ٨٩٥ | Q25: انثى | S25: عازب | V25: وزارة الإدارة المحلية و البيئة | W25: الأمانة العامة للمحافظة | X25: الأمانة العامة لمحافظة طرطوس | Y25: تكليف | AB25: ادارية | AC25: مثبت | AD25: على رأس عمله | AE25: 41214 | AF25: تعاقد مباشر | AH25: الفئة الثانية | AI25: شهاد ثانوية | AK25: طرطوس | AL25: طرطوس | AM25: ملك | AN25: لا | AQ25: سليم | AS25: A+ | AT25: شهادة ثانوية | AU25: نعم | AX25: علمي | AY25: 39736 | AZ25: لا | BA25: مكلفة لدى اتحاد عمال طرطوس | BB25: خارج المبنى | BC25: داخل الملاك | BD25: 526698988 | BE25: 14940 | BF25: 1226025
A26: 25 | B26: 1674 | C26: 1639557 | D26: بشار | E26: ابراهيم | F26: حصاوي | G26: =CONCATENATE(TRIM(الجدول2[[#This Row],[الاسم الأول]])," ",TRIM(الجدول2[[#This Row],[اسم الأب]])," ",TRIM(الجدول2[[#This Row],[الكنية]])) -> بشار ابراهيم حصاوي | H26: فاطمة حسن | I26: 04120004502 | J26: سوري | K26: حمص | L26: تلكلخ | M26: مركز منطقة تلكلخ | N26: تلكخ | O26: 32436 | P26: معربو١٨ | Q26: ذكر | R26: 0933445982 | S26: متزوج | T26: 1 | U26: 4 | V26: وزارة الإدارة المحلية و البيئة | W26: الأمانة العامة للمحافظة | X26: الأمانة العامة لمحافظة طرطوس | Y26: مديرية إدارة النفايات الصلبة | Z26: المركز المتكامل في وادي الهدة | AA26: محطة صافيتا | AB26: سائق | AC26: متعاقد | AD26: على رأس عمله | AE26: 45077 | AF26: مسابقة مركزية | AH26: الفئة الرابعة | AI26: شهادة إعدادية | AK26: طرطوس | AL26: صافيتا | AM26: إيجار | AN26: لا | AQ26: سليم | AS26: O- | AT26: قراءة وكتابة | AZ26: لا | BB26: خارج المبنى | BC26: داخل الملاك | BD26: 523186393 | BE26: 3009 | BF26: 918870
A27: 26 | B27: 1696 | D27: بشار | E27: عبدالكريم | F27: حاج معلا | G27: =CONCATENATE(TRIM(الجدول2[[#This Row],[الاسم الأول]])," ",TRIM(الجدول2[[#This Row],[اسم الأب]])," ",TRIM(الجدول2[[#This Row],[الكنية]])) -> بشار عبدالكريم حاج معلا | H27: سعده حاج معلا | I27: 10010079942 | J27: سوري | K27: طرطوس | L27: طرطوس | M27: مركز منطقة طرطوس | N27: طرطوس | O27: 26530 | P27: خراب اسلام ٨٩٥ | Q27: ذكر | R27: 0933844399 | S27: متزوج | T27: 1 | U27: 2 | V27: وزارة الإدارة المحلية و البيئة | W27: الأمانة العامة للمحافظة | X27: الأمانة العامة لمحافظة طرطوس | Y27: تكليف | AB27: عامل طباعه | AC27: متعاقد | AD27: على رأس عمله | AE27: 44054 | AF27: مسابقة مركزية | AH27: الفئة الرابعة | AI27: قراءة وكتابة | AK27: طرطوس | AL27: طرطوس | AM27: ملك | AN27: لا | AQ27: سليم | AS27: A+ | AT27: قراءة وكتابة | AZ27: لا | BA27: تكليف لدى اتحاد عمال طرطوس | BB27: خارج المبنى | BC27: داخل الملاك | BD27: 526704599 | BE27: 14969 | BF27: 1001241
A28: 27 | B28: 45065 | C28: 1639560 | D28: بهاء | E28: سلمان | F28: الموعي | G28: =CONCATENATE(TRIM(الجدول2[[#This Row],[الاسم الأول]])," ",TRIM(الجدول2[[#This Row],[اسم الأب]])," ",TRIM(الجدول2[[#This Row],[الكنية]])) -> بهاء سلمان الموعي | H28: كوكب عباس | I28: 10160106311 | J28: سوري | K28: طرطوس | L28: صافيتا | M28: مركز منطقة صافيتا | N28: راس مندو | O28: 29655 | P28: راس مندو6 | Q28: ذكر | R28: 0933714474 | S28: متزوج | T28: 1 | U28: 2 | V28: وزارة الإدارة المحلية و البيئة | W28: الأمانة العامة للمحافظة | X28: الأمانة العامة لمحافظة طرطوس | Y28: مديرية إدارة النفايات الصلبة | AB28: سائق | AC28: متعاقد | AD28: على رأس عمله | AE28: 45103 | AF28: مسابقة مركزية | AH28: الفئة الرابعة | AI28: قراءة وكتابة | AK28: طرطوس | AL28: صافيتا | AM28: ملك | AN28: لا | AQ28: سليم | AS28: A- | AT28: قراءة وكتابة | AZ28: لا | BB28: خارج المبنى | BC28: داخل الملاك | BD28: 536496866 | BE28: 33215 | BF28: 918870
A29: 28 | B29: 1833 | D29: تغريد | E29: محمود | F29: محمود | G29: =CONCATENATE(TRIM(الجدول2[[#This Row],[الاسم الأول]])," ",TRIM(الجدول2[[#This Row],[اسم الأب]])," ",TRIM(الجدول2[[#This Row],[الكنية]])) -> تغريد محمود محمود | H29: سهيلا سلمان | I29: 10010001039 | J29: سوري | K29: طرطوس | L29: طرطوس | M29: مركز منطقة طرطوس | N29: طرطوس | O29: 29590 | P29: الرمل ٣٤ | Q29: انثى | R29: 0982248472 | S29: متزوج | U29: 2 | V29: وزارة الإدارة المحلية و البيئة | W29: الأمانة العامة للمحافظة | X29: الأمانة العامة لمحافظة طرطوس | Y29: تكليف | AB29: عاملة حاسب | AC29: متعاقد | AD29: على رأس عمله | AE29: 40671 | AF29: مسابقة | AH29: الفئة الرابعة | AI29: شهادة إعدادية | AK29: طرطوس | AL29: طرطوس | AM29: ملك | AN29: نعم | AO29: فادي عبدالحميد حسن | AP29: مديرية الخدمات الفنية بطرطوس | AQ29: سليم | AS29: O+ | AT29: شهادة إعدادية | AU29: نعم | AY29: 35065 | AZ29: لا | BA29: مكلفة لدى بلدية يحمور | BB29: خارج المبنى | BC29: داخل الملاك | BD29: 526599205 | BE29: 13912 | BF29: 1185000
A30: 29 | B30: 1846 | C30: 1639577 | D30: تمام | E30: علي | F30: الزمريني | G30: =CONCATENATE(TRIM(الجدول2[[#This Row],[الاسم الأول]])," ",TRIM(الجدول2[[#This Row],[اسم الأب]])," ",TRIM(الجدول2[[#This Row],[الكنية]])) -> تمام علي الزمريني | H30: ملكه ابراهيم | I30: 10220046553 | J30: سوري | K30: طرطوس | L30: الدريكيش | M30: مركز منطقة الدريكيش | N30: بقعو | O30: 31778 | P30: بقعو ٨٧ | Q30: ذكر | R30: 0933289677 | S30: متزوج | T30: 1 | U30: 2 | V30: وزارة الإدارة المحلية و البيئة | W30: الأمانة العامة للمحافظة | X30: الأمانة العامة لمحافظة طرطوس | Y30: مديرية التنمية الإدارية | Z30: دائرة الديوان العام | AB30: مساعد اداري | AC30: متعاقد | AD30: على رأس عمله | AE30: 44336 | AF30: مسابقة | AH30: الفئة الاولى | AI30: إجازة جامعية 4 سنوات | AJ30: لغة فرنسية | AK30: طرطوس | AL30: طرطوس | AM30: ملك | AN30: لا | AQ30: سليم | AS30: O+ | AT30: إجازة جامعية 4 سنوات | AU30: نعم | AV30: جامعة اللادقية | AW30: كلية الآداب والعلوم الإنسانية | AX30: ادب فرنسي | AY30: 40765 | AZ30: لا | BB30: ضمن المبنى | BC30: داخل الملاك | BD30: 536049501 | BE30: 32136 | BF30: 1110357
A31: 30 | B31: 1882 | C31: 1634545 | D31: تيماء | E31: علي | F31: صافي | G31: =CONCATENATE(TRIM(الجدول2[[#This Row],[الاسم الأول]])," ",TRIM(الجدول2[[#This Row],[اسم الأب]])," ",TRIM(الجدول2[[#This Row],[الكنية]])) -> تيماء علي صافي | H31: وجود ديب | I31: 10040014648 | J31: سوري | K31: طرطوس | L31: طرطوس | M31: خربة المعزة | N31: طرطوس | O31: 36161 | P31: يمور ١٠٤ | Q31: انثى | R31: 0938732218 | S31: عازب | V31: وزارة الإدارة المحلية و البيئة | W31: الأمانة العامة للمحافظة | X31: الأمانة العامة لمحافظة طرطوس | Y31: مديرية دعم القرار والتخطيط الإقليمي | Z31: دائرة تحليل المعطيات | AB31: مهندسة | AC31: مثبت | AD31: على رأس عمله | AE31: 45494 | AF31: فرز مهندسين | AH31: الفئة الاولى | AI31: إجازة جامعية 5 سنوات | AJ31: هندسة مدنية | AK31: طرطوس | AL31: طرطوس | AM31: ملك | AN31: لا | AQ31: سليم | AS31: A+ | AT31: إجازة جامعية 5 سنوات | AU31: نعم | AV31: اللاذقية | AW31: هندسة مدنية | AX31: ادارة تشييد | AY31: 44546 | AZ31: لا | BB31: ضمن المبنى | BC31: داخل الملاك | BD31: 523948800 | BE31: 4769 | BF31: 943000
A32: 31 | B32: 1956 | C32: 1634852 | D32: جراح | E32: ابراهيم | F32: سليمان | G32: =CONCATENATE(TRIM(الجدول2[[#This Row],[الاسم الأول]])," ",TRIM(الجدول2[[#This Row],[اسم الأب]])," ",TRIM(الجدول2[[#This Row],[الكنية]])) -> جراح ابراهيم سليمان | H32: نجاح حمدان | I32: 10130016338 | J32: سوري | K32: طرطوس | L32: بانياس | M32: الروضة | N32: كرميا | O32: 29427 | P32: كرميا٨ | Q32: ذكر | R32: 0992170246 | S32: مطلق | U32: 0 | V32: وزارة الإدارة المحلية و البيئة | W32: الأمانة العامة للمحافظة | X32: الأمانة العامة لمحافظة طرطوس | Y32: مديرية الخدمات العامة | Z32: دائرة الخدمات الادارية | AA32: المستودع | AB32: أمين مستودع | AC32: مثبت | AD32: على رأس عمله | AE32: 41294 | AF32: مسابقة | AH32: الفئة الثانية | AI32: معهد متوسط | AJ32: معهد متوسط هندسة كمبيوتر | AK32: طرطوس | AL32: بانياس | AM32: أقارب | AN32: نعم | AO32: ايمان علي محمد | AP32: مديرية الخدمات الفنية | AQ32: سليم | AS32: O- | AT32: معهد متوسط | AU32: نعم | AV32: جامعة اللاذقية | AW32: معهد متوسط هندسة كمبيوتر | AX32: هندسة كمبيوتر | AY32: 37774 | AZ32: لا | BB32: ضمن المبنى | BC32: داخل الملاك | BD32: 523888168 | BE32: 4409 | BF32: 1243000
A33: 32 | B33: 2064 | D33: جميله | E33: بهجت | F33: اسماعيل | G33: =CONCATENATE(TRIM(الجدول2[[#This Row],[الاسم الأول]])," ",TRIM(الجدول2[[#This Row],[اسم الأب]])," ",TRIM(الجدول2[[#This Row],[الكنية]])) -> جميله بهجت اسماعيل | H33: ماريه حمدان | I33: 10260017185 | J33: سوري | K33: طرطوس | L33: الشيخ بدر | M33: مركز منطقة الشيخ بدر | N33: سريجس | O33: 32278 | P33: سريجس ١٩ | Q33: انثى | S33: متزوج | U33: 2 | V33: وزارة الإدارة المحلية و البيئة | W33: الأمانة العامة للمحافظة | X33: الأمانة العامة لمحافظة طرطوس | Y33: تكليف | AB33: ادارية | AC33: مثبت | AD33: على رأس عمله | AE33: 41294 | AF33: مسابقة | AH33: الفئة الثانية | AI33: شهاد ثانوية | AK33: طرطوس | AL33: الشيخ بدر | AM33: أقارب | AN33: لا | AQ33: سليم | AS33: A+ | AT33: إجازة جامعية 4 سنوات | AU33: نعم | AV33: اللاذقية | AW33: آداب | AX33: ادب عربي | AY33: 41318 | AZ33: لا | BA33: مكلفة لدى مجلس مدينة الشيخ بدر | BB33: خارج المبنى | BC33: داخل الملاك | BD33: 526104418 | BE33: 11126 | BF33: 1243000
A34: 33 | B34: 2065 | D34: جنان | E34: عمر | F34: الشيخ | G34: =CONCATENATE(TRIM(الجدول2[[#This Row],[الاسم الأول]])," ",TRIM(الجدول2[[#This Row],[اسم الأب]])," ",TRIM(الجدول2[[#This Row],[الكنية]])) -> جنان عمر الشيخ | H34: فاطمة أخضر | I34: 10010078192 | J34: سوري | K34: طرطوس | L34: طرطوس | M34: مركز منطقة طرطوس | N34: طرطوس | O34: 30730 | P34: خراب اسلام 945 | Q34: انثى | R34: 0994891990 | S34: متزوج | U34: 2 | V34: وزارة الإدارة المحلية و البيئة | W34: الأمانة العامة للمحافظة | X34: الأمانة العامة لمحافظة طرطوس | Y34: مركز خدمات المحافظة | AB34: موظفة استقبال | AC34: مثبت | AD34: على رأس عمله | AE34: 40860 | AF34: مسابقة | AH34: الفئة الثانية | AI34: معهد متوسط | AJ34: معهد مصرفي | AK34: طرطوس | AL34: طرطوس | AM34: ملك | AN34: لا | AQ34: سليم | AS34: AB+ | AT34: معهد متوسط | AU34: نعم | AV34: جامعة اللاذقية | AW34: معهد متوسط | AX34: معهد مصرفي | AY34: 38026 | AZ34: لا | BB34: ضمن المبنى | BC34: داخل الملاك | BD34: 526080524 | BE34: 10684 | BF34: 1243000
A35: 34 | B35: 2066 | D35: جنان | E35: منير | F35: نبهان | G35: =CONCATENATE(TRIM(الجدول2[[#This Row],[الاسم الأول]])," ",TRIM(الجدول2[[#This Row],[اسم الأب]])," ",TRIM(الجدول2[[#This Row],[الكنية]])) -> جنان منير نبهان | H35: ندى احمد | I35: 10050003634 | J35: سوري | K35: طرطوس | L35: طرطوس | M35: مركز منطقة طرطوس | N35: طرطوس | O35: 32334 | P35: خراب678 | Q35: انثى | R35: 0993818256 | S35: متزوج | U35: 2 | V35: وزارة الإدارة المحلية و البيئة | W35: الأمانة العامة للمحافظة | X35: الأمانة العامة لمحافظة طرطوس | Y35: تكليف | AB35: ادارية | AC35: مثبت | AD35: على رأس عمله | AE35: 41294 | AF35: مسابقة | AH35: الفئة الثانية | AI35: شهاد ثانوية | AK35: طرطوس | AL35: طرطوس | AM35: ملك | AN35: لا | AQ35: سليم | AS35: O+ | AT35: إجازة جامعية 4 سنوات | AU35: نعم | AV35: اللاذقية | AW35: اداب | AX35: تاريخ | AY35: 40386 | AZ35: نعم | BA35: مكلفة لدى بلدية بسورم | BB35: خارج المبنى | BC35: داخل الملاك | BD35: 526068834 | BE35: 10462 | BF35: 1243000
A36: 35 | B36: 2082 | C36: 775321 | D36: جهاد | E36: عبدالكريم | F36: قميره | G36: =CONCATENATE(TRIM(الجدول2[[#This Row],[الاسم الأول]])," ",TRIM(الجدول2[[#This Row],[اسم الأب]])," ",TRIM(الجدول2[[#This Row],[الكنية]])) -> جهاد عبدالكريم قميره | H36: فاطمة خضور | I36: 10010012541 | J36: سوري | K36: طرطوس | L36: طرطوس | M36: مركز منطقة طرطوس | N36: بانياس | O36: 26056 | P36: الحمرات ٣٠٨ | Q36: ذكر | R36: 0933686872 | S36: متزوج | T36: 1 | U36: 2 | V36: وزارة الإدارة المحلية و البيئة | W36: الأمانة العامة للمحافظة | X36: الأمانة العامة لمحافظة طرطوس | Y36: مديرية الخدمات العامة | AB36: مدير الخدمات العامة | AC36: مثبت | AD36: على رأس عمله | AE36: 35399 | AF36: مسابقة | AH36: الفئة الاولى | AI36: إجازة جامعية 4 سنوات | AJ36: أدب فرنسي | AK36: طرطوس | AL36: طرطوس | AM36: ملك | AN36: نعم | AO36: سمر شوكت درغام | AP36: مديرية التربية | AQ36: سليم | AS36: O+ | AT36: إجازة جامعية 4 سنوات | AU36: نعم | AV36: دمشق | AW36: آداب | AX36: ادب فرنسي | AY36: 33817 | AZ36: لا | BB36: ضمن المبنى | BC36: داخل الملاك | BD36: 526124137 | BE36: 11331 | BF36: 1409000
A37: 36 | B37: 2121 | D37: جومانا | E37: احمد | F37: عمران | G37: =CONCATENATE(TRIM(الجدول2[[#This Row],[الاسم الأول]])," ",TRIM(الجدول2[[#This Row],[اسم الأب]])," ",TRIM(الجدول2[[#This Row],[الكنية]])) -> جومانا احمد عمران | H37: سليمة محرز | I37: 10230010545 | J37: سوري | K37: طرطوس | L37: الدريكيش | M37: مركز منطقة الدريكيش | N37: بشمشة | O37: 31234 | P37: بشمشة ٢١ | Q37: انثى | R37: 0992897166 | S37: عازب | V37: وزارة الإدارة المحلية و البيئة | W37: الأمانة العامة للمحافظة | X37: الأمانة العامة لمحافظة طرطوس | Y37: مديرية التنمية الإدارية | Z37: دائرة الديوان العام | AA37: الوراد | AB37: ادراي | AC37: مثبت | AD37: على رأس عمله | AE37: 41304 | AF37: مسابقة | AH37: الفئة الثانية | AI37: شهاد ثانوية | AK37: طرطوس | AL37: الدريكيش | AM37: ملك | AN37: لا | AQ37: سليم | AS37: B+ | AT37: شهادة ثانوية | AU37: نعم | AX37: لا | AY37: 38557 | AZ37: لا | BB37: ضمن المبنى | BC37: داخل الملاك | BD37: 523946995 | BE37: 4760 | BF37: 1243000
A38: 37 | B38: 2191 | C38: 1639599 | D38: حسام | E38: جابر | F38: عمار | G38: =CONCATENATE(TRIM(الجدول2[[#This Row],[الاسم الأول]])," ",TRIM(الجدول2[[#This Row],[اسم الأب]])," ",TRIM(الجدول2[[#This Row],[الكنية]])) -> حسام جابر عمار | H38: هاجر الشيخ | I38: 10280010962 | J38: سوري | K38: طرطوس | L38: طرطوس | M38: مركز منطقة طرطوس | N38: طرطوس | O38: 31529 | P38: الجباب ٢٥ | Q38: ذكر | R38: 0933048295 | S38: عازب | V38: وزارة الإدارة المحلية و البيئة | W38: الأمانة العامة للمحافظة | X38: الأمانة العامة لمحافظة طرطوس | Y38: مديرية الخدمات العامة | Z38: دائرة الآليات | AB38: محاسب محروقات | AC38: مثبت | AD38: على رأس عمله | AE38: 41275 | AF38: مسابقة | AH38: الفئة الاولى | AI38: إجازة جامعية 4 سنوات | AJ38: تجارة واقتصاد - نشروعات صغيرة | AK38: طرطوس | AL38: طرطوس | AM38: إيجار | AN38: لا | AQ38: سليم | AS38: AB+ | AT38: إجازة جامعية 4 سنوات | AU38: لا | AV38: طرطوس | AW38: اقتصاد | AX38: مشروعات صغيرة | AY38: 45536 | AZ38: لا | BB38: ضمن المبنى | BC38: داخل الملاك | BD38: 526127664 | BE38: 11358 | BF38: 1243000
A39: 38 | B39: 2205 | D39: حسام | E39: عقل | F39: محمود | G39: =CONCATENATE(TRIM(الجدول2[[#This Row],[الاسم الأول]])," ",TRIM(الجدول2[[#This Row],[اسم الأب]])," ",TRIM(الجدول2[[#This Row],[الكنية]])) -> حسام عقل محمود | H39: خضرة علي | I39: 10260017794 | J39: سوري | K39: طرطوس | L39: الشيخ بدر | M39: مركز منطقة الشيخ بدر | N39: فندراة | O39: 28902 | P39: النويحة ١٠ | Q39: ذكر | R39: 0936885218 | S39: متزوج | T39: 1 | U39: 2 | V39: وزارة الإدارة المحلية و البيئة | W39: الأمانة العامة للمحافظة | X39: الأمانة العامة لمحافظة طرطوس | Y39: تكليف | AB39: اداري | AC39: مثبت | AD39: على رأس عمله | AE39: 41294 | AF39: مسابقة | AH39: الفئة الثانية | AI39: شهاد ثانوية | AK39: طرطوس | AL39: الشيخ بدر | AM39: ملك | AN39: نعم | AO39: لبنى علي علي | AP39: مديرية الصحة | AQ39: سليم | AS39: AB+ | AT39: معهد متوسط | AU39: نعم | AV39: اللاذقية | AW39: معهد متوسط | AX39: تجارة | AY39: 36161 | AZ39: لا | BA39: مكلف الى مجلس مدينة الشيخ بدر | BB39: خارج المبنى | BC39: داخل الملاك | BD39: 526120046 | BE39: 11300 | BF39: 1243000
A40: 39 | B40: 2231 | C40: 2000627 | D40: حسان | E40: احمد | F40: ديوب | G40: =CONCATENATE(TRIM(الجدول2[[#This Row],[الاسم الأول]])," ",TRIM(الجدول2[[#This Row],[اسم الأب]])," ",TRIM(الجدول2[[#This Row],[الكنية]])) -> حسان احمد ديوب | H40: نوال خضور | I40: 10270009352 | J40: سوري | K40: طرطوس | L40: طرطوس | M40: مركز منطقة طرطوس | N40: دمشق | O40: 33530 | P40: تلة ١٩ | Q40: ذكر | R40: 0937902315 | S40: عازب | V40: وزارة الإدارة المحلية و البيئة | W40: الأمانة العامة للمحافظة | X40: الأمانة العامة لمحافظة طرطوس | Y40: مديرية الشؤون القانونية | Z40: دائرة الإفراز والاستملاك | AB40: رئيس شعبة | AC40: مثبت | AD40: على رأس عمله | AE40: 42561 | AF40: فرز مهندسين | AH40: الفئة الاولى | AI40: إجازة جامعية 5 سنوات | AJ40: هندسة | AK40: طرطوس | AL40: طرطوس | AM40: ملك | AN40: لا | AQ40: سليم | AS40: A+ | AT40: إجازة جامعية 5 سنوات | AU40: نعم | AV40: اللاذقية | AW40: هندسة | AX40: مدنية | AY40: 41844 | AZ40: لا | BB40: ضمن المبنى | BC40: داخل الملاك | BD40: 524048773 | BE40: 5657 | BF40: 1254291
...

Sheet احصائية 1
A1: إحصائية العاملين لدى الأمانة العامة لمحافظة طرطوس 2025/10/8
E2: مجموع | F2: ضمن المبنى | G2: خارج المبنى | H2: بلا آجر | I2: ملاحظات
A3: ملاك الأمانة العامة | C3: دائم | D3: =COUNTIFS('العاملين الأمانة العامة'!AC:AC,"مثبت",'العاملين الأمانة العامة'!BC:BC,"داخل الملاك") -> 209 | E3: =SUM(D3:D4) -> 281 | F3: =COUNTIFS('العاملين الأمانة العامة'!BB:BB,"ضمن المبنى",'العاملين الأمانة العامة'!BC:BC,"داخل الملاك") -> 179 | G3: =COUNTIFS('العاملين الأمانة العامة'!BB:BB,"خارج المبنى",'العاملين الأمانة العامة'!BC:BC,"داخل الملاك") -> 89 | H3: =COUNTIFS('العاملين الأمانة العامة'!AD:AD,"إجازة بلا أجر",'العاملين الأمانة العامة'!BC:BC,"داخل الملاك") -> 13 | I3: يشمل العاملين في النفايات الصلبة داخل وخارج المبنى والمجازين بلا اجر
C4: مؤقت | D4: =COUNTIFS('العاملين الأمانة العامة'!AC:AC,"متعاقد",'العاملين الأمانة العامة'!BC:BC,"داخل الملاك") -> 72
A5: مكلفين/ مندبين إلى الأمانة العامة | C5: تكليف | D5: =COUNTIFS('العاملين الأمانة العامة'!AA:AA,"مكلف",'العاملين الأمانة العامة'!BC:BC,"خارج الملاك") -> 81 | E5: =SUM(D5:D6) -> 83 | F5: =COUNTIFS('العاملين الأمانة العامة'!BB:BB,"ضمن المبنى",'العاملين الأمانة العامة'!AA:AA,"مكلف",'العاملين الأمانة العامة'!BC:BC,"خارج الملاك") -> 80 | G5: =COUNTIFS('العاملين الأمانة العامة'!BB:BB,"خارج المبنى",'العاملين الأمانة العامة'!AA:AA,"مكلف",'العاملين الأمانة العامة'!BC:BC,"خارج الملاك") -> 0 | H5: =COUNTIFS('العاملين الأمانة العامة'!AD:AD,"إجازة بلا أجر",'العاملين الأمانة العامة'!BC:BC,"خارج الملاك") -> 1 | I5: المكلفة مدى غانم إجازة بلا أجر
C6: ندب | D6: =COUNTIFS('العاملين الأمانة العامة'!AA:AA,"مندب",'العاملين الأمانة العامة'!BC:BC,"خارج الملاك") -> 2 | F6: =COUNTIFS('العاملين الأمانة العامة'!BB:BB,"ضمن المبنى",'العاملين الأمانة العامة'!AA:AA,"مندب",'العاملين الأمانة العامة'!BC:BC,"خارج الملاك") -> 1 | G6: =COUNTIFS('العاملين الأمانة العامة'!BB:BB,"خارج المبنى",'العاملين الأمانة العامة'!AA:AA,"مندب",'العاملين الأمانة العامة'!BC:BC,"خارج الملاك") -> 1 | I6: عواطف حيدر مندبة ومكلفة في بلدية الدكيكة
A7: مركز العريضة | F7: - | G7: 8
A8: تحت التصرف | F8: - | G8: =COUNTIFS('العاملين الأمانة العامة'!BB:BB,"خارج المبنى",'العاملين الأمانة العامة'!AA:AA,"تحت التصرف",'العاملين الأمانة العامة'!BC:BC,"خارج الملاك") -> 3
A9: الوضع الراهن ضمن المبنى/خارج المبنى/إجازات | F9: =SUM(F3:F8) -> 260 | G9: =SUM(G3:G8) -> 101 | H9: =SUM(H3:H8) -> 14
A10: كافة العاملين | F10: =SUM(F9:H9) -> 375
A13: تفصيل العمال خارج المبنى و مديرية النفايات | E13: مجموع | F13: ضمن المبنى | G13: خارج المبنى | H13: بلا آجر | I13: ملاحظات
A14: مكلفين/ مندبين من الأمانة العامة | C14: تكليف | E14: =COUNTIFS('العاملين الأمانة العامة'!Y:Y,"تكليف",'العاملين الأمانة العامة'!BC:BC,"داخل الملاك") -> 75 | F14: =COUNTIFS('العاملين الأمانة العامة'!BB:BB,"ضمن المبنى",'العاملين الأمانة العامة'!BC:BC,"داخل الملاك",'العاملين الأمانة العامة'!Y:Y,"تكليف") -> 0 | G14: =COUNTIFS('العاملين الأمانة العامة'!BB:BB,"خارج المبنى",'العاملين الأمانة العامة'!BC:BC,"داخل الملاك",'العاملين الأمانة العامة'!Y:Y,"تكليف") -> 75 | I14: العدد الإجمالي للعمال خارج المبنى يشمل المكلفين خارج المبنى وعمال مديرية إدارة النفايات الصلبة العاملين في دوائر المديرية خارج المبنى
A15: مديرية إدارة النفايات الصلبة | C15: دائم | D15: =COUNTIFS('العاملين الأمانة العامة'!AC:AC,"مثبت",'العاملين الأمانة العامة'!Y:Y,A15,'العاملين الأمانة العامة'!BC:BC,"داخل الملاك") -> 10 | E15: =SUM(D15:D16) -> 19 | F15: =COUNTIFS('العاملين الأمانة العامة'!BB:BB,"ضمن المبنى",'العاملين الأمانة العامة'!Y:Y,A15,'العاملين الأمانة العامة'!BC:BC,"داخل الملاك") -> 4 | G15: =COUNTIFS('العاملين الأمانة العامة'!BB:BB,"خارج المبنى",'العاملين الأمانة العامة'!Y:Y,A15,'العاملين الأمانة العامة'!BC:BC,"داخل الملاك") -> 14 | H15: =COUNTIFS('العاملين الأمانة العامة'!AD:AD,"إجازة بلا أجر",'العاملين الأمانة العامة'!Y:Y,A15,'العاملين الأمانة العامة'!BC:BC,"داخل الملاك") -> 1
C16: مؤقت | D16: =COUNTIFS('العاملين الأمانة العامة'!AC:AC,"متعاقد",'العاملين الأمانة العامة'!Y:Y,A15,'العاملين الأمانة العامة'!BC:BC,"داخل الملاك") -> 9
G17: =SUM(G14:G16) -> 89

Sheet احصائية 2
A1: إحصائية العاملين لدى الأمانة العامة لمحافظة طرطوس 2025/10/8
E2: مجموع | F2: ضمن المبنى | G2: خارج المبنى | I2: ملاحظات
A3: ملاك الأمانة العامة | C3: دائم | D3: ='احصائية 1'!D3-'احصائية 1'!D15 -> 199 | E3: =SUM(D3:D4) -> 262 | F3: ='احصائية 1'!F3-'احصائية 1'!F15 -> 175 | G3: ='احصائية 1'!G3-'احصائية 1'!G15 -> 75 | I3: بدون احتساب مركز العريضة والنفايات الصلبة
C4: مؤقت | D4: ='احصائية 1'!D4-'احصائية 1'!D16 -> 63
A5: مديرية إدارة النفايات الصلبة | C5: دائم | D5: 10 | E5: =SUM(D5:D6) -> 19 | F5: ='احصائية 1'!F15 -> 4 | G5: ='احصائية 1'!G15 -> 14 | I5: يشمل محمد عمران إجازة بلا اجر
C6: مؤقت | D6: 9
A7: مكلفين/ مندبين إلى الأمانة العامة | C7: تكليف | D7: ='احصائية 1'!D5 -> 81 | E7: =SUM(D7:D8) -> 83 | F7: ='احصائية 1'!F5 -> 80 | G7: ='احصائية 1'!G5 -> 0 | I7: مدى غانم إجازة بلا أجر
C8: ندب | D8: ='احصائية 1'!D6 -> 2 | F8: ='احصائية 1'!F6 -> 1 | G8: ='احصائية 1'!G6 -> 1 | I8: عواطف حيدر مندبة ومكلفة في بلدية الدكيكة
A9: مركز العريضة | G9: ='احصائية 1'!G7 -> 8
A10: تحت التصرف | G10: ='احصائية 1'!G8 -> 3
A11: الوضع الراهن ضمن المبنى/ خارج المبنى | F11: =SUM(F3:F10) -> 260 | G11: =SUM(G3:G10) -> 101
A12: كافة العاملين | F12: =SUM(F11:G11) -> 361
A15: مكلفين/ مندبين خارج الأمانة العامة | C15: تكليف | E15: ='احصائية 1'!#REF! -> #REF! | F15: ='احصائية 1'!#REF! -> #REF! | G15: ='احصائية 1'!#REF! -> #REF! | I15: تم حذف ندى تقلا مكلفة في مجلس المدينة منحت إجازة بلا اجر
A16: إجازة بلا أجر | E16: ='احصائية 1'!#REF! -> #REF! | G16: ='احصائية 1'!#REF! -> #REF! | I16: بدون محمد عمران
G17: =SUM(G15:G16) -> #REF!
